[2024-01-05T10:29:31.395+0000] {taskinstance.py:1957} INFO - Dependencies all met for dep_context=non-requeueable deps ti=<TaskInstance: load_data.load_data_instacart manual__2024-01-05T10:29:23+00:00 [queued]>
[2024-01-05T10:29:31.412+0000] {taskinstance.py:1957} INFO - Dependencies all met for dep_context=requeueable deps ti=<TaskInstance: load_data.load_data_instacart manual__2024-01-05T10:29:23+00:00 [queued]>
[2024-01-05T10:29:31.413+0000] {taskinstance.py:2171} INFO - Starting attempt 1 of 1
[2024-01-05T10:29:31.438+0000] {taskinstance.py:2192} INFO - Executing <Task(PythonOperator): load_data_instacart> on 2024-01-05 10:29:23+00:00
[2024-01-05T10:29:31.445+0000] {standard_task_runner.py:60} INFO - Started process 340 to run task
[2024-01-05T10:29:31.450+0000] {standard_task_runner.py:87} INFO - Running: ['***', 'tasks', 'run', 'load_data', 'load_data_instacart', 'manual__2024-01-05T10:29:23+00:00', '--job-id', '18', '--raw', '--subdir', 'DAGS_FOLDER/load_data.py', '--cfg-path', '/tmp/tmpisj2kcya']
[2024-01-05T10:29:31.453+0000] {standard_task_runner.py:88} INFO - Job 18: Subtask load_data_instacart
[2024-01-05T10:29:31.534+0000] {task_command.py:423} INFO - Running <TaskInstance: load_data.load_data_instacart manual__2024-01-05T10:29:23+00:00 [running]> on host edef6e683abd
[2024-01-05T10:29:31.682+0000] {taskinstance.py:2481} INFO - Exporting env vars: AIRFLOW_CTX_DAG_OWNER='***' AIRFLOW_CTX_DAG_ID='load_data' AIRFLOW_CTX_TASK_ID='load_data_instacart' AIRFLOW_CTX_EXECUTION_DATE='2024-01-05T10:29:23+00:00' AIRFLOW_CTX_TRY_NUMBER='1' AIRFLOW_CTX_DAG_RUN_ID='manual__2024-01-05T10:29:23+00:00'
[2024-01-05T10:29:31.834+0000] {taskinstance.py:2699} ERROR - Task failed with exception
Traceback (most recent call last):
  File "/home/airflow/.local/lib/python3.8/site-packages/airflow/models/taskinstance.py", line 433, in _execute_task
    result = execute_callable(context=context, **execute_callable_kwargs)
  File "/home/airflow/.local/lib/python3.8/site-packages/airflow/operators/python.py", line 199, in execute
    return_value = self.execute_callable()
  File "/home/airflow/.local/lib/python3.8/site-packages/airflow/operators/python.py", line 216, in execute_callable
    return self.python_callable(*self.op_args, **self.op_kwargs)
  File "/opt/airflow/dags/load_data.py", line 35, in load_data
    reader = pd.read_parquet(path + filename + ".parquet", chunksize=chunk_size)
  File "/home/airflow/.local/lib/python3.8/site-packages/pandas/io/parquet.py", line 509, in read_parquet
    return impl.read(
  File "/home/airflow/.local/lib/python3.8/site-packages/pandas/io/parquet.py", line 220, in read
    path_or_handle, handles, kwargs["filesystem"] = _get_path_or_handle(
  File "/home/airflow/.local/lib/python3.8/site-packages/pandas/io/parquet.py", line 110, in _get_path_or_handle
    handles = get_handle(
  File "/home/airflow/.local/lib/python3.8/site-packages/pandas/io/common.py", line 868, in get_handle
    handle = open(handle, ioargs.mode)
FileNotFoundError: [Errno 2] No such file or directory: '/opt/airflow/data/instacart-market-basket-analysis/sample_submission.par.parquet'
[2024-01-05T10:29:31.858+0000] {taskinstance.py:1138} INFO - Marking task as FAILED. dag_id=load_data, task_id=load_data_instacart, execution_date=20240105T102923, start_date=20240105T102931, end_date=20240105T102931
[2024-01-05T10:29:31.882+0000] {standard_task_runner.py:107} ERROR - Failed to execute job 18 for task load_data_instacart ([Errno 2] No such file or directory: '/opt/airflow/data/instacart-market-basket-analysis/sample_submission.par.parquet'; 340)
[2024-01-05T10:29:31.905+0000] {local_task_job_runner.py:234} INFO - Task exited with return code 1
[2024-01-05T10:29:31.932+0000] {taskinstance.py:3281} INFO - 0 downstream tasks scheduled from follow-on schedule check
