[2023-12-30T17:43:28.828+0000] {taskinstance.py:1957} INFO - Dependencies all met for dep_context=non-requeueable deps ti=<TaskInstance: load_data.load_data_orders manual__2023-12-30T17:43:00.699453+00:00 [queued]>
[2023-12-30T17:43:28.847+0000] {taskinstance.py:1957} INFO - Dependencies all met for dep_context=requeueable deps ti=<TaskInstance: load_data.load_data_orders manual__2023-12-30T17:43:00.699453+00:00 [queued]>
[2023-12-30T17:43:28.847+0000] {taskinstance.py:2171} INFO - Starting attempt 1 of 1
[2023-12-30T17:43:28.886+0000] {taskinstance.py:2192} INFO - Executing <Task(PythonOperator): load_data_orders> on 2023-12-30 17:43:00.699453+00:00
[2023-12-30T17:43:28.898+0000] {standard_task_runner.py:60} INFO - Started process 134 to run task
[2023-12-30T17:43:28.901+0000] {standard_task_runner.py:87} INFO - Running: ['***', 'tasks', 'run', 'load_data', 'load_data_orders', 'manual__2023-12-30T17:43:00.699453+00:00', '--job-id', '4', '--raw', '--subdir', 'DAGS_FOLDER/load_data.py', '--cfg-path', '/tmp/tmpqonf51e1']
[2023-12-30T17:43:28.927+0000] {standard_task_runner.py:88} INFO - Job 4: Subtask load_data_orders
[2023-12-30T17:43:29.247+0000] {task_command.py:423} INFO - Running <TaskInstance: load_data.load_data_orders manual__2023-12-30T17:43:00.699453+00:00 [running]> on host edef6e683abd
[2023-12-30T17:43:29.579+0000] {taskinstance.py:2481} INFO - Exporting env vars: AIRFLOW_CTX_DAG_OWNER='***' AIRFLOW_CTX_DAG_ID='load_data' AIRFLOW_CTX_TASK_ID='load_data_orders' AIRFLOW_CTX_EXECUTION_DATE='2023-12-30T17:43:00.699453+00:00' AIRFLOW_CTX_TRY_NUMBER='1' AIRFLOW_CTX_DAG_RUN_ID='manual__2023-12-30T17:43:00.699453+00:00'
[2023-12-30T17:44:50.149+0000] {local_task_job_runner.py:302} WARNING - State of this instance has been externally set to failed. Terminating instance.
[2023-12-30T17:44:50.155+0000] {process_utils.py:131} INFO - Sending 15 to group 134. PIDs of all processes in the group: [134]
[2023-12-30T17:44:50.155+0000] {process_utils.py:86} INFO - Sending the signal 15 to group 134
[2023-12-30T17:44:50.156+0000] {taskinstance.py:2451} ERROR - Received SIGTERM. Terminating subprocesses.
[2023-12-30T17:44:50.249+0000] {process_utils.py:79} INFO - Process psutil.Process(pid=134, status='terminated', exitcode=0, started='17:43:28') (134) terminated with exit code 0
