[2023-12-30T17:43:20.832+0000] {scheduler_job_runner.py:781} ERROR - Executor reports task instance <TaskInstance: load_data.load_data_task manual__2023-12-30T17:43:00.699453+00:00 [queued]> finished (failed) although the task says it's queued. (Info: None) Was the task killed externally?
