[2024-01-05T10:47:13.772+0000] {taskinstance.py:1957} INFO - Dependencies all met for dep_context=non-requeueable deps ti=<TaskInstance: load_data_parquet.load_data_instacart manual__2024-01-05T10:47:08.691556+00:00 [queued]>
[2024-01-05T10:47:13.783+0000] {taskinstance.py:1957} INFO - Dependencies all met for dep_context=requeueable deps ti=<TaskInstance: load_data_parquet.load_data_instacart manual__2024-01-05T10:47:08.691556+00:00 [queued]>
[2024-01-05T10:47:13.783+0000] {taskinstance.py:2171} INFO - Starting attempt 1 of 1
[2024-01-05T10:47:13.807+0000] {taskinstance.py:2192} INFO - Executing <Task(PythonOperator): load_data_instacart> on 2024-01-05 10:47:08.691556+00:00
[2024-01-05T10:47:13.813+0000] {standard_task_runner.py:60} INFO - Started process 53 to run task
[2024-01-05T10:47:13.826+0000] {standard_task_runner.py:87} INFO - Running: ['***', 'tasks', 'run', 'load_data_parquet', 'load_data_instacart', 'manual__2024-01-05T10:47:08.691556+00:00', '--job-id', '23', '--raw', '--subdir', 'DAGS_FOLDER/load_data_parquet.py', '--cfg-path', '/tmp/tmpzccq9qca']
[2024-01-05T10:47:13.832+0000] {standard_task_runner.py:88} INFO - Job 23: Subtask load_data_instacart
[2024-01-05T10:47:13.962+0000] {task_command.py:423} INFO - Running <TaskInstance: load_data_parquet.load_data_instacart manual__2024-01-05T10:47:08.691556+00:00 [running]> on host edef6e683abd
[2024-01-05T10:47:14.156+0000] {taskinstance.py:2481} INFO - Exporting env vars: AIRFLOW_CTX_DAG_OWNER='***' AIRFLOW_CTX_DAG_ID='load_data_parquet' AIRFLOW_CTX_TASK_ID='load_data_instacart' AIRFLOW_CTX_EXECUTION_DATE='2024-01-05T10:47:08.691556+00:00' AIRFLOW_CTX_TRY_NUMBER='1' AIRFLOW_CTX_DAG_RUN_ID='manual__2024-01-05T10:47:08.691556+00:00'
[2024-01-05T10:47:15.157+0000] {taskinstance.py:2699} ERROR - Task failed with exception
Traceback (most recent call last):
  File "/home/airflow/.local/lib/python3.8/site-packages/airflow/models/taskinstance.py", line 433, in _execute_task
    result = execute_callable(context=context, **execute_callable_kwargs)
  File "/home/airflow/.local/lib/python3.8/site-packages/airflow/operators/python.py", line 199, in execute
    return_value = self.execute_callable()
  File "/home/airflow/.local/lib/python3.8/site-packages/airflow/operators/python.py", line 216, in execute_callable
    return self.python_callable(*self.op_args, **self.op_kwargs)
  File "/opt/airflow/dags/load_data_parquet.py", line 34, in load_data
    reader.to_sql(table_name, engine, if_exists='replace', index=False, schema=schemaName)
NameError: name 'table_name' is not defined
[2024-01-05T10:47:15.179+0000] {taskinstance.py:1138} INFO - Marking task as FAILED. dag_id=load_data_parquet, task_id=load_data_instacart, execution_date=20240105T104708, start_date=20240105T104713, end_date=20240105T104715
[2024-01-05T10:47:15.206+0000] {standard_task_runner.py:107} ERROR - Failed to execute job 23 for task load_data_instacart (name 'table_name' is not defined; 53)
[2024-01-05T10:47:15.243+0000] {local_task_job_runner.py:234} INFO - Task exited with return code 1
[2024-01-05T10:47:15.277+0000] {taskinstance.py:3281} INFO - 0 downstream tasks scheduled from follow-on schedule check
