[2024-01-05T10:36:43.305+0000] {taskinstance.py:1957} INFO - Dependencies all met for dep_context=non-requeueable deps ti=<TaskInstance: load_data.load_data_instacart manual__2024-01-05T10:36:38.390530+00:00 [queued]>
[2024-01-05T10:36:43.318+0000] {taskinstance.py:1957} INFO - Dependencies all met for dep_context=requeueable deps ti=<TaskInstance: load_data.load_data_instacart manual__2024-01-05T10:36:38.390530+00:00 [queued]>
[2024-01-05T10:36:43.319+0000] {taskinstance.py:2171} INFO - Starting attempt 1 of 1
[2024-01-05T10:36:43.340+0000] {taskinstance.py:2192} INFO - Executing <Task(PythonOperator): load_data_instacart> on 2024-01-05 10:36:38.390530+00:00
[2024-01-05T10:36:43.345+0000] {standard_task_runner.py:60} INFO - Started process 394 to run task
[2024-01-05T10:36:43.349+0000] {standard_task_runner.py:87} INFO - Running: ['***', 'tasks', 'run', 'load_data', 'load_data_instacart', 'manual__2024-01-05T10:36:38.390530+00:00', '--job-id', '20', '--raw', '--subdir', 'DAGS_FOLDER/load_data.py', '--cfg-path', '/tmp/tmp4j9vegc4']
[2024-01-05T10:36:43.352+0000] {standard_task_runner.py:88} INFO - Job 20: Subtask load_data_instacart
[2024-01-05T10:36:43.429+0000] {task_command.py:423} INFO - Running <TaskInstance: load_data.load_data_instacart manual__2024-01-05T10:36:38.390530+00:00 [running]> on host edef6e683abd
[2024-01-05T10:36:43.560+0000] {taskinstance.py:2481} INFO - Exporting env vars: AIRFLOW_CTX_DAG_OWNER='***' AIRFLOW_CTX_DAG_ID='load_data' AIRFLOW_CTX_TASK_ID='load_data_instacart' AIRFLOW_CTX_EXECUTION_DATE='2024-01-05T10:36:38.390530+00:00' AIRFLOW_CTX_TRY_NUMBER='1' AIRFLOW_CTX_DAG_RUN_ID='manual__2024-01-05T10:36:38.390530+00:00'
[2024-01-05T10:36:43.595+0000] {taskinstance.py:2699} ERROR - Task failed with exception
Traceback (most recent call last):
  File "/home/airflow/.local/lib/python3.8/site-packages/airflow/models/taskinstance.py", line 433, in _execute_task
    result = execute_callable(context=context, **execute_callable_kwargs)
  File "/home/airflow/.local/lib/python3.8/site-packages/airflow/operators/python.py", line 199, in execute
    return_value = self.execute_callable()
  File "/home/airflow/.local/lib/python3.8/site-packages/airflow/operators/python.py", line 216, in execute_callable
    return self.python_callable(*self.op_args, **self.op_kwargs)
  File "/opt/airflow/dags/load_data.py", line 35, in load_data
    reader = pd.read_parquet(path + filename + ".parquet", engine='pyarrow', chunksize=chunk_size)
  File "/home/airflow/.local/lib/python3.8/site-packages/pandas/io/parquet.py", line 509, in read_parquet
    return impl.read(
  File "/home/airflow/.local/lib/python3.8/site-packages/pandas/io/parquet.py", line 227, in read
    pa_table = self.api.parquet.read_table(
TypeError: read_table() got an unexpected keyword argument 'chunksize'
[2024-01-05T10:36:43.614+0000] {taskinstance.py:1138} INFO - Marking task as FAILED. dag_id=load_data, task_id=load_data_instacart, execution_date=20240105T103638, start_date=20240105T103643, end_date=20240105T103643
[2024-01-05T10:36:43.630+0000] {standard_task_runner.py:107} ERROR - Failed to execute job 20 for task load_data_instacart (read_table() got an unexpected keyword argument 'chunksize'; 394)
[2024-01-05T10:36:43.643+0000] {local_task_job_runner.py:234} INFO - Task exited with return code 1
[2024-01-05T10:36:43.667+0000] {taskinstance.py:3281} INFO - 0 downstream tasks scheduled from follow-on schedule check
