[2023-12-30T01:39:56.085+0000] {taskinstance.py:1957} INFO - Dependencies all met for dep_context=non-requeueable deps ti=<TaskInstance: load_data.load_data_task manual__2023-12-30T01:39:28.841654+00:00 [queued]>
[2023-12-30T01:39:56.114+0000] {taskinstance.py:1957} INFO - Dependencies all met for dep_context=requeueable deps ti=<TaskInstance: load_data.load_data_task manual__2023-12-30T01:39:28.841654+00:00 [queued]>
[2023-12-30T01:39:56.115+0000] {taskinstance.py:2171} INFO - Starting attempt 1 of 1
[2023-12-30T01:39:56.156+0000] {taskinstance.py:2192} INFO - Executing <Task(PythonOperator): load_data_task> on 2023-12-30 01:39:28.841654+00:00
[2023-12-30T01:39:56.176+0000] {standard_task_runner.py:60} INFO - Started process 290 to run task
[2023-12-30T01:39:56.193+0000] {standard_task_runner.py:87} INFO - Running: ['***', 'tasks', 'run', 'load_data', 'load_data_task', 'manual__2023-12-30T01:39:28.841654+00:00', '--job-id', '2', '--raw', '--subdir', 'DAGS_FOLDER/load_data.py', '--cfg-path', '/tmp/tmpgtmth3nw']
[2023-12-30T01:39:56.295+0000] {standard_task_runner.py:88} INFO - Job 2: Subtask load_data_task
[2023-12-30T01:39:57.091+0000] {task_command.py:423} INFO - Running <TaskInstance: load_data.load_data_task manual__2023-12-30T01:39:28.841654+00:00 [running]> on host 3196336a5b49
[2023-12-30T01:39:57.917+0000] {taskinstance.py:2481} INFO - Exporting env vars: AIRFLOW_CTX_DAG_OWNER='***' AIRFLOW_CTX_DAG_ID='load_data' AIRFLOW_CTX_TASK_ID='load_data_task' AIRFLOW_CTX_EXECUTION_DATE='2023-12-30T01:39:28.841654+00:00' AIRFLOW_CTX_TRY_NUMBER='1' AIRFLOW_CTX_DAG_RUN_ID='manual__2023-12-30T01:39:28.841654+00:00'
[2023-12-30T01:39:57.922+0000] {taskinstance.py:2699} ERROR - Task failed with exception
Traceback (most recent call last):
  File "/home/airflow/.local/lib/python3.8/site-packages/airflow/models/taskinstance.py", line 433, in _execute_task
    result = execute_callable(context=context, **execute_callable_kwargs)
  File "/home/airflow/.local/lib/python3.8/site-packages/airflow/operators/python.py", line 199, in execute
    return_value = self.execute_callable()
  File "/home/airflow/.local/lib/python3.8/site-packages/airflow/operators/python.py", line 216, in execute_callable
    return self.python_callable(*self.op_args, **self.op_kwargs)
  File "/opt/airflow/dags/load_data.py", line 31, in load_data
    df = pd.read_csv(path + "products.csv", header=True)
  File "/home/airflow/.local/lib/python3.8/site-packages/pandas/io/parsers/readers.py", line 912, in read_csv
    return _read(filepath_or_buffer, kwds)
  File "/home/airflow/.local/lib/python3.8/site-packages/pandas/io/parsers/readers.py", line 577, in _read
    parser = TextFileReader(filepath_or_buffer, **kwds)
  File "/home/airflow/.local/lib/python3.8/site-packages/pandas/io/parsers/readers.py", line 1401, in __init__
    self.options, self.engine = self._clean_options(options, engine)
  File "/home/airflow/.local/lib/python3.8/site-packages/pandas/io/parsers/readers.py", line 1571, in _clean_options
    validate_header_arg(options["header"])
  File "/home/airflow/.local/lib/python3.8/site-packages/pandas/io/common.py", line 208, in validate_header_arg
    raise TypeError(
TypeError: Passing a bool to header is invalid. Use header=None for no header or header=int or list-like of ints to specify the row(s) making up the column names
[2023-12-30T01:39:58.031+0000] {taskinstance.py:1138} INFO - Marking task as FAILED. dag_id=load_data, task_id=load_data_task, execution_date=20231230T013928, start_date=20231230T013956, end_date=20231230T013958
[2023-12-30T01:39:58.089+0000] {standard_task_runner.py:107} ERROR - Failed to execute job 2 for task load_data_task (Passing a bool to header is invalid. Use header=None for no header or header=int or list-like of ints to specify the row(s) making up the column names; 290)
[2023-12-30T01:39:58.122+0000] {local_task_job_runner.py:234} INFO - Task exited with return code 1
[2023-12-30T01:39:58.166+0000] {taskinstance.py:3281} INFO - 0 downstream tasks scheduled from follow-on schedule check
