[2023-12-30T02:38:29.441+0000] {taskinstance.py:1957} INFO - Dependencies all met for dep_context=non-requeueable deps ti=<TaskInstance: load_data.load_data_task manual__2023-12-30T02:38:18.191511+00:00 [queued]>
[2023-12-30T02:38:29.463+0000] {taskinstance.py:1957} INFO - Dependencies all met for dep_context=requeueable deps ti=<TaskInstance: load_data.load_data_task manual__2023-12-30T02:38:18.191511+00:00 [queued]>
[2023-12-30T02:38:29.464+0000] {taskinstance.py:2171} INFO - Starting attempt 1 of 1
[2023-12-30T02:38:29.495+0000] {taskinstance.py:2192} INFO - Executing <Task(PythonOperator): load_data_task> on 2023-12-30 02:38:18.191511+00:00
[2023-12-30T02:38:29.506+0000] {standard_task_runner.py:60} INFO - Started process 149 to run task
[2023-12-30T02:38:29.511+0000] {standard_task_runner.py:87} INFO - Running: ['***', 'tasks', 'run', 'load_data', 'load_data_task', 'manual__2023-12-30T02:38:18.191511+00:00', '--job-id', '11', '--raw', '--subdir', 'DAGS_FOLDER/load_data.py', '--cfg-path', '/tmp/tmpp6pcx3tz']
[2023-12-30T02:38:29.519+0000] {standard_task_runner.py:88} INFO - Job 11: Subtask load_data_task
[2023-12-30T02:38:30.339+0000] {task_command.py:423} INFO - Running <TaskInstance: load_data.load_data_task manual__2023-12-30T02:38:18.191511+00:00 [running]> on host 39cba3469596
[2023-12-30T02:38:30.940+0000] {taskinstance.py:2481} INFO - Exporting env vars: AIRFLOW_CTX_DAG_OWNER='***' AIRFLOW_CTX_DAG_ID='load_data' AIRFLOW_CTX_TASK_ID='load_data_task' AIRFLOW_CTX_EXECUTION_DATE='2023-12-30T02:38:18.191511+00:00' AIRFLOW_CTX_TRY_NUMBER='1' AIRFLOW_CTX_DAG_RUN_ID='manual__2023-12-30T02:38:18.191511+00:00'
[2023-12-30T02:38:30.946+0000] {logging_mixin.py:188} INFO - this is a test
[2023-12-30T02:38:30.947+0000] {logging_mixin.py:188} INFO - ***
[2023-12-30T02:38:30.948+0000] {logging_mixin.py:188} INFO - ['dags', 'logs', 'data', '***.cfg', 'plugins']
[2023-12-30T02:38:31.795+0000] {taskinstance.py:2699} ERROR - Task failed with exception
Traceback (most recent call last):
  File "/home/airflow/.local/lib/python3.8/site-packages/airflow/models/taskinstance.py", line 433, in _execute_task
    result = execute_callable(context=context, **execute_callable_kwargs)
  File "/home/airflow/.local/lib/python3.8/site-packages/airflow/operators/python.py", line 199, in execute
    return_value = self.execute_callable()
  File "/home/airflow/.local/lib/python3.8/site-packages/airflow/operators/python.py", line 216, in execute_callable
    return self.python_callable(*self.op_args, **self.op_kwargs)
  File "/opt/airflow/dags/load_data.py", line 33, in load_data
    engine = create_engine('postgresql://airflow:airflow@172.17.0.1:5432:5432/airflow')
  File "<string>", line 2, in create_engine
  File "/home/airflow/.local/lib/python3.8/site-packages/sqlalchemy/util/deprecations.py", line 375, in warned
    return fn(*args, **kwargs)
  File "/home/airflow/.local/lib/python3.8/site-packages/sqlalchemy/engine/create.py", line 514, in create_engine
    u = _url.make_url(url)
  File "/home/airflow/.local/lib/python3.8/site-packages/sqlalchemy/engine/url.py", line 738, in make_url
    return _parse_url(name_or_url)
  File "/home/airflow/.local/lib/python3.8/site-packages/sqlalchemy/engine/url.py", line 794, in _parse_url
    components["port"] = int(components["port"])
ValueError: invalid literal for int() with base 10: '5432:5432'
[2023-12-30T02:38:31.942+0000] {taskinstance.py:1138} INFO - Marking task as FAILED. dag_id=load_data, task_id=load_data_task, execution_date=20231230T023818, start_date=20231230T023829, end_date=20231230T023831
[2023-12-30T02:38:32.022+0000] {standard_task_runner.py:107} ERROR - Failed to execute job 11 for task load_data_task (invalid literal for int() with base 10: '5432:5432'; 149)
[2023-12-30T02:38:32.063+0000] {local_task_job_runner.py:234} INFO - Task exited with return code 1
[2023-12-30T02:38:32.105+0000] {taskinstance.py:3281} INFO - 0 downstream tasks scheduled from follow-on schedule check
